Workbook

Sheet retornos
B1: CAGR (96-24) | C1: CAGR (98-24) | D1: CAGR (00-24) | E1: CAGR (10-24) | F1: CAGR (20-24) | G1: DESV PAD (96 - 24) | H1: DESV PAD (98-24) | I1: SHARPE (96 - 24) | J1: SHARPE (98 - 24) | K1: 1996 | L1: 1997 | M1: 1998 | N1: 1999 | O1: 2000 | P1: 2001 | Q1: 2002 | R1: 2003 | S1: 2004 | T1: 2005 | U1: 2006 | V1: 2007 | W1: 2008 | X1: 2009 | Y1: 2010 | Z1: 2011 | AA1: 2012 | AB1: 2013 | AC1: 2014 | AD1: 2015 | AE1: 2016 | AF1: 2017 | AG1: 2018 | AH1: 2019 | AI1: 2020 | AJ1: 2021 | AK1: 2022 | AL1: 2023 | AM1: 2024
A2: CDI | B2: {=GEOMEAN(1+K2:AM2)-1} -> 0.138518 | C2: {=GEOMEAN(1+M2:AM2)-1} -> 0.13129946 | D2: {=GEOMEAN(1+O2:AM2)-1} -> 0.11990469 | E2: {=GEOMEAN(1+Y2:AM2)-1} -> 0.097262895 | F2: {=GEOMEAN(1+AI2:AM2)-1} -> 0.10469628 | G2: 0.017691 | H2: 0.015906 | K2: 0.20978182 | L2: 0.27219999 | M2: 0.39259998 | N2: 0.18370001 | O2: 0.1572 | P2: 0.18549999 | Q2: 0.2623 | R2: 0.1602 | S2: 0.1921 | T2: 0.1651 | U2: 0.1266 | V2: 0.1115 | W2: 0.1108 | X2: 0.0861 | Y2: 0.1166 | Z2: 0.0952 | AA2: 0.0701 | AB2: 0.1055 | AC2: 0.126 | AD2: 0.1413 | AE2: 0.1213 | AF2: 0.0639 | AG2: 0.064 | AH2: 0.0365 | AI2: 0.0265 | AJ2: 0.1165 | AK2: 0.1365 | AL2: 0.1065 | AM2: 0.1415
A3: IBOVESPA | B3: {=GEOMEAN(1+K3:AM3)-1} -> 0.11932898 | C3: {=GEOMEAN(1+M3:AM3)-1} -> 0.092519379 | D3: {=GEOMEAN(1+O3:AM3)-1} -> 0.082819514 | E3: {=GEOMEAN(1+Y3:AM3)-1} -> 0.041904038 | F3: {=GEOMEAN(1+AI3:AM3)-1} -> 0.12272612 | G3: 0.2722 | H3: 0.26798 | I3: =(B3-$B$2)/G3 -> -0.070496032 | J3: =(C3-$B$2)/H3 -> -0.17164944 | K3: 0.82526388 | L3: 0.32087572 | M3: -0.10463754 | N3: 0.66604338 | O3: -0.18978676 | P3: -0.082005818 | Q3: -0.14946431 | R3: 0.96416216 | S3: 0.20178846 | T3: 0.42619316 | U3: 0.20692472 | V3: 0.33106279 | W3: -0.32874623 | X3: 0.7195113 | Y3: -0.025365563 | Z3: -0.059429038 | AA3: -0.12646101 | AB3: -0.10537337 | AC3: 0.014599119 | AD3: -0.021407625 | AE3: 0.29825192 | AF3: 0.31363967 | AG3: 0.11771726 | AH3: -0.23471051 | AI3: 0.59728983 | AJ3: 0.028855377 | AK3: -0.15097622 | AL3: 0.25739432 | AM3: 0.016809816
A4: IBRX-100 | B4: {=GEOMEAN(1+K4:AM4)-1} -> 0.14320425 | C4: {=GEOMEAN(1+M4:AM4)-1} -> 0.12454876 | D4: {=GEOMEAN(1+O4:AM4)-1} -> 0.11855353 | E4: {=GEOMEAN(1+Y4:AM4)-1} -> 0.062873665 | F4: {=GEOMEAN(1+AI4:AM4)-1} -> 0.12318035 | G4: 0.255161 | H4: 0.251448 | I4: =(B4-$B$2)/G4 -> 0.018365864 | J4: =(C4-$B$2)/H4 -> -0.055555154 | K4: 0.6614 | L4: 0.2266 | M4: -0.1722 | N4: 0.7461 | O4: -0.0454 | P4: 0.0647 | Q4: -0.0106 | R4: 0.8043 | S4: 0.3357 | T4: 0.4994 | U4: 0.226 | V4: 0.3455 | W4: -0.3123 | X4: 0.5998 | Y4: 0.0134 | Z4: -0.0156 | AA4: -0.0229 | AB4: -0.032 | AC4: 0.0169 | AD4: -0.0253 | AE4: 0.2976 | AF4: 0.3126 | AG4: 0.1267 | AH4: -0.222 | AI4: 0.6217 | AJ4: 0.0279 | AK4: -0.1605 | AL4: 0.2518 | AM4: 0.0204
A5: TOP 5 MF1 | B5: {=GEOMEAN(1+K5:AM5)-1} -> 0.22564542 | C5: {=GEOMEAN(1+M5:AM5)-1} -> 0.21034812 | D5: {=GEOMEAN(1+O5:AM5)-1} -> 0.20274259 | E5: {=GEOMEAN(1+Y5:AM5)-1} -> 0.12029247 | F5: {=GEOMEAN(1+AI5:AM5)-1} -> 0.25150207 | G5: 0.2793523 | H5: 0.28345225 | I5: =(B5-$B$2)/G5 -> 0.31189083 | J5: =(C5-$B$2)/H5 -> 0.25341174 | K5: 0.89885926 | L5: 0.11047713 | M5: 0.0081541833 | N5: 0.7011161 | O5: 0.2408977 | P5: -0.033439784 | Q5: 0.45844718 | R5: 0.9623466 | S5: 0.51012602 | T5: 0.096557035 | U5: 0.50067721 | V5: 0.083329281 | W5: -0.13211648 | X5: 1.2917173 | Y5: 0.28500742 | Z5: 0.37738438 | AA5: -0.17007342 | AB5: -0.20267711 | AC5: -0.061287615 | AD5: -0.02867611 | AE5: 0.23659813 | AF5: 0.9591903 | AG5: -0.19361472 | AH5: -0.14210475 | AI5: 1.6706975 | AJ5: 0.054022991 | AK5: -0.086394304 | AL5: 0.41838964 | AM5: -0.15835543
A6: TOP 10 MF1 | B6: {=GEOMEAN(1+K6:AM6)-1} -> 0.23882648 | C6: {=GEOMEAN(1+M6:AM6)-1} -> 0.23359205 | D6: {=GEOMEAN(1+O6:AM6)-1} -> 0.2225751 | E6: {=GEOMEAN(1+Y6:AM6)-1} -> 0.13038282 | F6: {=GEOMEAN(1+AI6:AM6)-1} -> 0.19315226 | G6: 0.24084492 | H6: 0.24544863 | I6: =(B6-$B$2)/G6 -> 0.41648578 | J6: =(C6-$B$2)/H6 -> 0.38734808 | K6: 0.63282234 | L6: 0.053738388 | M6: -0.092126378 | N6: 1.097578 | O6: 0.31524526 | P6: 0.22712093 | Q6: 0.47818812 | R6: 0.65860442 | S6: 0.55494102 | T6: 0.18663417 | U6: 0.44563711 | V6: 0.19541497 | W6: -0.16345892 | X6: 1.2910935 | Y6: 0.25422097 | Z6: 0.14740326 | AA6: -0.031187322 | AB6: -0.16650305 | AC6: -0.12628972 | AD6: -0.14958884 | AE6: 0.80582218 | AF6: 0.63297842 | AG6: -0.013902555 | AH6: 0.035376332 | AI6: 1.3806162 | AJ6: 0.14254525 | AK6: -0.22987225 | AL6: 0.23222993 | AM6: -0.063167327
A7: TOP 15 MF1 | B7: {=GEOMEAN(1+K7:AM7)-1} -> 0.22157047 | C7: {=GEOMEAN(1+M7:AM7)-1} -> 0.21923208 | D7: {=GEOMEAN(1+O7:AM7)-1} -> 0.20920383 | E7: {=GEOMEAN(1+Y7:AM7)-1} -> 0.11074369 | F7: {=GEOMEAN(1+AI7:AM7)-1} -> 0.17839884 | G7: 0.21254925 | H7: 0.21565506 | I7: =(B7-$B$2)/G7 -> 0.3907446 | J7: =(C7-$B$2)/H7 -> 0.374274 | K7: 0.53951971 | L7: 0.020750755 | M7: -0.088357207 | N7: 1.0045628 | O7: 0.23400676 | P7: 0.26233515 | Q7: 0.46606505 | R7: 0.81733753 | S7: 0.59721154 | T7: 0.17995962 | U7: 0.45460857 | V7: 0.23209973 | W7: -0.23036152 | X7: 1.2145765 | Y7: 0.32134826 | Z7: 0.19075616 | AA7: -0.029275893 | AB7: -0.20173781 | AC7: -0.10954203 | AD7: -0.18633192 | AE7: 0.6793813 | AF7: 0.45046797 | AG7: 0.033359891 | AH7: -0.043477947 | AI7: 1.1343564 | AJ7: 0.12703491 | AK7: -0.24640043 | AL7: 0.35699926 | AM7: -0.076287167
A8: TOP 20 MF1 | B8: {=GEOMEAN(1+K8:AM8)-1} -> 0.22031991 | C8: {=GEOMEAN(1+M8:AM8)-1} -> 0.22702304 | D8: {=GEOMEAN(1+O8:AM8)-1} -> 0.21516092 | E8: {=GEOMEAN(1+Y8:AM8)-1} -> 0.10998643 | F8: {=GEOMEAN(1+AI8:AM8)-1} -> 0.1720793 | G8: 0.2017502 | H8: 0.20408121 | I8: =(B8-$B$2)/G8 -> 0.40546138 | J8: =(C8-$B$2)/H8 -> 0.43367561 | K8: 0.28824283 | L8: -0.0029519233 | M8: -0.15884742 | N8: 1.2819374 | O8: 0.30129181 | P8: 0.31429457 | Q8: 0.39131929 | R8: 1.0787528 | S8: 0.5156541 | T8: 0.14782406 | U8: 0.4723204 | V8: 0.27178177 | W8: -0.21242622 | X8: 1.1508058 | Y8: 0.26093466 | Z8: 0.27247126 | AA8: 0.063597382 | AB8: -0.16385629 | AC8: -0.15563027 | AD8: -0.11924465 | AE8: 0.6082109 | AF8: 0.36221619 | AG8: 0.042192498 | AH8: -0.10740106 | AI8: 1.0036053 | AJ8: 0.076007239 | AK8: -0.17307271 | AL8: 0.34106148 | AM8: -0.074787263
A9: TOP 30 MF1 | B9: {=GEOMEAN(1+K9:AM9)-1} -> 0.22814189 | C9: {=GEOMEAN(1+M9:AM9)-1} -> 0.23362852 | D9: {=GEOMEAN(1+O9:AM9)-1} -> 0.22418196 | E9: {=GEOMEAN(1+Y9:AM9)-1} -> 0.12388731 | F9: {=GEOMEAN(1+AI9:AM9)-1} -> 0.20245478 | G9: 0.18816383 | H9: 0.190028 | I9: =(B9-$B$2)/G9 -> 0.47630774 | J9: =(C9-$B$2)/H9 -> 0.50050793 | K9: 0.24322863 | L9: 0.075667298 | M9: -0.13296983 | N9: 1.1271359 | O9: 0.22334274 | P9: 0.21545805 | Q9: 0.35505379 | R9: 1.2375165 | S9: 0.49210531 | T9: 0.15573682 | U9: 0.54018442 | V9: 0.34936763 | W9: -0.19953487 | X9: 1.1066532 | Y9: 0.31108292 | Z9: 0.18740135 | AA9: 0.13458714 | AB9: -0.10710881 | AC9: -0.15108877 | AD9: -0.10544632 | AE9: 0.46328636 | AF9: 0.33090765 | AG9: 0.068953162 | AH9: -0.080124432 | AI9: 1.016619 | AJ9: 0.060307803 | AK9: -0.11578147 | AL9: 0.37258183 | AM9: -0.03129824
A10: Quintil 1 MF1 | B10: {=GEOMEAN(1+K10:AM10)-1} -> 0.24205877 | C10: {=GEOMEAN(1+M10:AM10)-1} -> 0.23646204 | D10: {=GEOMEAN(1+O10:AM10)-1} -> 0.22827094 | E10: {=GEOMEAN(1+Y10:AM10)-1} -> 0.12817148 | F10: {=GEOMEAN(1+AI10:AM10)-1} -> 0.21426106 | G10: 0.19530499 | H10: 0.1967169 | I10: =(B10-$B$2)/G10 -> 0.53014916 | J10: =(C10-$B$2)/H10 -> 0.49789342 | K10: 0.70734474 | L10: 0.020750755 | M10: -0.12106743 | N10: 1.0538622 | O10: 0.27352873 | P10: 0.26233515 | Q10: 0.53366352 | R10: 0.828813 | S10: 0.64943608 | T10: 0.17995962 | U10: 0.46615282 | V10: 0.18785847 | W10: -0.18676563 | X10: 1.2505186 | Y10: 0.25981317 | Z10: 0.18740135 | AA10: 0.13076471 | AB10: -0.12256286 | AC10: -0.1647112 | AD10: -0.11378303 | AE10: 0.52263111 | AF10: 0.39216225 | AG10: 0.070077583 | AH10: -0.072106929 | AI10: 1.0003592 | AJ10: 0.048103335 | AK10: -0.097773766 | AL10: 0.37072531 | AM10: 0.01808105
A11: Quintil 2 MF1 | B11: {=GEOMEAN(1+K11:AM11)-1} -> 0.23101456 | C11: {=GEOMEAN(1+M11:AM11)-1} -> 0.24384306 | D11: {=GEOMEAN(1+O11:AM11)-1} -> 0.22576488 | E11: {=GEOMEAN(1+Y11:AM11)-1} -> 0.15179082 | F11: {=GEOMEAN(1+AI11:AM11)-1} -> 0.17034106 | G11: 0.20302245 | H11: 0.20337577 | I11: =(B11-$B$2)/G11 -> 0.45559774 | J11: =(C11-$B$2)/H11 -> 0.51788403 | K11: 0.045621305 | L11: 0.095436586 | M11: -0.096885771 | N11: 1.4702953 | O11: 0.34157162 | P11: 0.20618299 | Q11: 0.24294227 | R11: 1.3224828 | S11: 0.35660305 | T11: 0.11348032 | U11: 0.59239425 | V11: 0.420639 | W11: -0.36323453 | X11: 0.91644075 | Y11: 0.26287397 | Z11: 0.17376745 | AA11: 0.23253015 | AB11: -0.058287646 | AC11: -0.10271301 | AD11: 0.05064425 | AE11: 0.31681856 | AF11: 0.3848934 | AG11: 0.23982467 | AH11: 0.034414258 | AI11: 0.82957253 | AJ11: 0.078895421 | AK11: -0.12150755 | AL11: 0.40751673 | AM11: -0.10041619
A12: Quintil 3 MF1 | B12: {=GEOMEAN(1+K12:AM12)-1} -> 0.22707175 | C12: {=GEOMEAN(1+M12:AM12)-1} -> 0.23127635 | D12: {=GEOMEAN(1+O12:AM12)-1} -> 0.19849335 | E12: {=GEOMEAN(1+Y12:AM12)-1} -> 0.11295892 | F12: {=GEOMEAN(1+AI12:AM12)-1} -> 0.20617722 | G12: 0.2495047 | H12: 0.25278001 | I12: =(B12-$B$2)/G12 -> 0.35491816 | J12: =(C12-$B$2)/H12 -> 0.36695291 | K12: 0.43329071 | L12: -0.042155779 | M12: 0.69129853 | N12: 0.75990228 | O12: 0.11088938 | P12: 0.098300763 | Q12: 0.18666094 | R12: 1.5220302 | S12: 0.4299778 | T12: 0.49831522 | U12: 0.31326153 | V12: 0.045630185 | W12: -0.34201038 | X12: 1.6263574 | Y12: 0.19475293 | Z12: 0.079769607 | AA12: 0.10608064 | AB12: -0.15820224 | AC12: -0.082310885 | AD12: -0.15571663 | AE12: 0.34418841 | AF12: 0.31185729 | AG12: 0.19925929 | AH12: -0.0089763923 | AI12: 0.85609602 | AJ12: 0.12611657 | AK12: -0.15031338 | AL12: 0.34327184 | AM12: 0.070161023
A13: Quintil 4 MF1 | B13: {=GEOMEAN(1+K13:AM13)-1} -> 0.11420525 | C13: {=GEOMEAN(1+M13:AM13)-1} -> 0.1175847 | D13: {=GEOMEAN(1+O13:AM13)-1} -> 0.1263117 | E13: {=GEOMEAN(1+Y13:AM13)-1} -> 0.048467922 | F13: {=GEOMEAN(1+AI13:AM13)-1} -> 0.075572143 | G13: 0.22942859 | H13: 0.23098363 | I13: =(B13-$B$2)/G13 -> -0.10597085 | J13: =(C13-$B$2)/H13 -> -0.090626743 | K13: 0.32957359 | L13: -0.13958818 | M13: -0.43909071 | N13: 0.83322007 | O13: 0.39553634 | P13: -0.034690821 | Q13: -0.058488766 | R13: 0.73204962 | S13: 0.29159672 | T13: 0.44617326 | U13: 0.39741065 | V13: 0.35039196 | W13: -0.367171 | X13: 0.96302894 | Y13: 0.15251828 | Z13: -0.069735776 | AA13: 0.092217054 | AB13: -0.10832357 | AC13: -0.10373051 | AD13: -0.11611201 | AE13: 0.38485303 | AF13: 0.19153936 | AG13: 0.14770593 | AH13: -0.098053952 | AI13: 1.0637494 | AJ13: -0.085708273 | AK13: -0.33096267 | AL13: 0.29509577 | AM13: -0.11955194
A14: Quintil 5 MF1 | B14: {=GEOMEAN(1+K14:AM14)-1} -> 0.094627067 | C14: {=GEOMEAN(1+M14:AM14)-1} -> 0.09186209 | D14: {=GEOMEAN(1+O14:AM14)-1} -> 0.082601098 | E14: {=GEOMEAN(1+Y14:AM14)-1} -> 0.016828791 | F14: {=GEOMEAN(1+AI14:AM14)-1} -> 0.0058248052 | G14: 0.23197177 | H14: 0.23229967 | I14: =(B14-$B$2)/G14 -> -0.18920806 | J14: =(C14-$B$2)/H14 -> -0.20084361 | K14: 0.46721154 | L14: -0.12562786 | M14: -0.20740933 | N14: 0.86110007 | O14: 0.17260291 | P14: -0.095559737 | Q14: -0.095954106 | R14: 1.0671014 | S14: 0.34995583 | T14: 0.69224247 | U14: 0.29694356 | V14: -0.063610352 | W14: -0.52550044 | X14: 1.1702777 | Y14: -0.027206384 | Z14: -0.10190655 | AA14: 0.019920334 | AB14: -0.048009771 | AC14: -0.21320349 | AD14: -0.11955732 | AE14: 0.48173173 | AF14: 0.27205669 | AG14: 0.13428278 | AH14: -0.0068749769 | AI14: 0.5448765 | AJ14: -0.19266058 | AK14: -0.34674106 | AL14: 0.43293676 | AM14: -0.11824202
... A114: Quintil 5 MF11 | B114: {=GEOMEAN(1+K114:AM114)-1} -> 0.11744854 | C114: {=GEOMEAN(1+M114:AM114)-1} -> 0.11979248 | D114: {=GEOMEAN(1+O114:AM114)-1} -> 0.07737289 | E114: {=GEOMEAN(1+Y114:AM114)-1} -> 0.024163644 | F114: {=GEOMEAN(1+AI114:AM114)-1} -> -0.0043939668 | G114: 0.28712668 | H114: 0.29365902 | I114: =(B114-$B$2)/G114 -> -0.073380334 | J114: =(C114-$B$2)/H114 -> -0.063766185 | K114: 0.283487 | L114: -0.080623809 | M114: 1.2110462 | N114: 0.48924058 | O114: 0.15003769 | P114: -0.085529567 | Q114: -0.027458101 | R114: 0.53515486 | S114: 0.29806922 | T114: 0.66491133 | U114: 0.23944581 | V114: 0.0065682537 | W114: -0.57045 | X114: 1.4768233 | Y114: 0.039753844 | Z114: -0.090862388 | AA114: 0.071766514 | AB114: -0.04454481 | AC114: -0.11120019 | AD114: -0.087128017 | AE114: 0.2493346 | AF114: 0.24654207 | AG114: 0.1399963 | AH114: 0.048887915 | AI114: 0.90410399 | AJ114: -0.10961084 | AK114: -0.44595049 | AL114: 0.28690661 | AM114: -0.19077094
A115: TOP 30 MF4 + Markowitz | C115: {=GEOMEAN(1+M115:AM115)-1} -> 0.23386273 | D115: {=GEOMEAN(1+O115:AM115)-1} -> 0.22096465 | E115: {=GEOMEAN(1+Y115:AM115)-1} -> 0.14134079 | F115: {=GEOMEAN(1+AI115:AM115)-1} -> 0.19893015 | H115: 0.18622659 | J115: =(C115-$B$2)/H115 -> 0.51198238 | M115: -0.023503356 | N115: 1.0274809 | O115: 0.1441376 | P115: 0.33336077 | Q115: 0.39668314 | R115: 0.81491829 | S115: 0.51821826 | T115: 0.28380656 | U115: 0.56921407 | V115: 0.16434663 | W115: -0.21938118 | X115: 0.88334131 | Y115: 0.27790126 | Z115: 0.27383379 | AA115: 0.27703386 | AB115: -0.1022822 | AC115: -0.1548329 | AD115: -0.058443973 | AE115: 0.3854271 | AF115: 0.21511568 | AG115: 0.21126217 | AH115: -0.031543464 | AI115: 1.0696808 | AJ115: 0.098271813 | AK115: -0.14629787 | AL115: 0.26482226 | AM115: 0.0093001541
A116: TOP 30 MF2 + Markowitz | C116: {=GEOMEAN(1+M116:AM116)-1} -> 0.22143203 | D116: {=GEOMEAN(1+O116:AM116)-1} -> 0.21378197 | E116: {=GEOMEAN(1+Y116:AM116)-1} -> 0.12749266 | F116: {=GEOMEAN(1+AI116:AM116)-1} -> 0.16718275 | H116: 0.18532155 | J116: =(C116-$B$2)/H116 -> 0.44740631 | M116: -0.10396762 | N116: 0.94818615 | O116: 0.16664999 | P116: 0.35219681 | Q116: 0.37928435 | R116: 0.91200584 | S116: 0.4918192 | T116: 0.28440421 | U116: 0.51341157 | V116: 0.15854906 | W116: -0.17555585 | X116: 0.82069438 | Y116: 0.29660923 | Z116: 0.30145689 | AA116: 0.27978553 | AB116: -0.10836028 | AC116: -0.15334036 | AD116: -0.073091618 | AE116: 0.35426839 | AF116: 0.21897374 | AG116: 0.17233641 | AH116: -0.045119518 | AI116: 0.87213646 | AJ116: 0.063210576 | AK116: -0.13479098 | AL116: 0.24206083 | AM116: 0.0126832
A117: TOP 30 MF10 + Markowitz | C117: {=GEOMEAN(1+M117:AM117)-1} -> 0.25232398 | D117: {=GEOMEAN(1+O117:AM117)-1} -> 0.24858246 | E117: {=GEOMEAN(1+Y117:AM117)-1} -> 0.17143139 | F117: {=GEOMEAN(1+AI117:AM117)-1} -> 0.18682621 | H117: 0.18373091 | J117: =(C117-$B$2)/H117 -> 0.61941666 | M117: -0.1216271 | N117: 0.92415975 | O117: 0.28370454 | P117: 0.32103401 | Q117: 0.42535886 | R117: 0.96977961 | S117: 0.58263281 | T117: 0.16645816 | U117: 0.45847705 | V117: 0.40231653 | W117: -0.31000107 | X117: 0.93247349 | Y117: 0.38355938 | Z117: 0.22632938 | AA117: 0.25392178 | AB117: -0.1105809 | AC117: -0.042984892 | AD117: -0.00069355464 | AE117: 0.3004608 | AF117: 0.57764747 | AG117: 0.32248897 | AH117: -0.071635289 | AI117: 0.64990386 | AJ117: 0.15372915 | AK117: -0.1236362 | AL117: 0.32008253 | AM117: 0.069270577

Sheet Planilha2
B1: CAGR (96-24) | C1: CAGR (98-24) | D1: CAGR (00-24) | E1: CAGR (10-24) | F1: CAGR (20-24) | G1: DESV PAD (96 - 24) | H1: DESV PAD (98-24) | I1: SHARPE (96 - 24) | J1: SHARPE (98 - 24) | K1: 1996 | L1: 1997 | M1: 1998 | N1: 1999 | O1: 2000 | P1: 2001 | Q1: 2002 | R1: 2003 | S1: 2004 | T1: 2005 | U1: 2006 | V1: 2007 | W1: 2008 | X1: 2009 | Y1: 2010 | Z1: 2011 | AA1: 2012 | AB1: 2013 | AC1: 2014 | AD1: 2015 | AE1: 2016 | AF1: 2017 | AG1: 2018 | AH1: 2019 | AI1: 2020 | AJ1: 2021 | AK1: 2022 | AL1: 2023 | AM1: 2024
A2: CDI | B2: {=GEOMEAN(1+K2:AM2)-1} -> 0.138518 | C2: {=GEOMEAN(1+M2:AM2)-1} -> 0.13129946 | D2: {=GEOMEAN(1+O2:AM2)-1} -> 0.11990469 | E2: {=GEOMEAN(1+Y2:AM2)-1} -> 0.097262895 | F2: {=GEOMEAN(1+AI2:AM2)-1} -> 0.10469628 | G2: 0.017691 | H2: 0.015906 | K2: 0.20978182 | L2: 0.27219999 | M2: 0.39259998 | N2: 0.18370001 | O2: 0.1572 | P2: 0.18549999 | Q2: 0.2623 | R2: 0.1602 | S2: 0.1921 | T2: 0.1651 | U2: 0.1266 | V2: 0.1115 | W2: 0.1108 | X2: 0.0861 | Y2: 0.1166 | Z2: 0.0952 | AA2: 0.0701 | AB2: 0.1055 | AC2: 0.126 | AD2: 0.1413 | AE2: 0.1213 | AF2: 0.0639 | AG2: 0.064 | AH2: 0.0365 | AI2: 0.0265 | AJ2: 0.1165 | AK2: 0.1365 | AL2: 0.1065 | AM2: 0.1415
A3: IBOVESPA | B3: {=GEOMEAN(1+K3:AM3)-1} -> 0.11932898 | C3: {=GEOMEAN(1+M3:AM3)-1} -> 0.092519379 | D3: {=GEOMEAN(1+O3:AM3)-1} -> 0.082819514 | E3: {=GEOMEAN(1+Y3:AM3)-1} -> 0.041904038 | F3: {=GEOMEAN(1+AI3:AM3)-1} -> 0.12272612 | G3: 0.2722 | H3: 0.26798 | I3: =(B3-$B$2)/G3 -> -0.070496032 | J3: =(C3-$B$2)/H3 -> -0.17164944 | K3: 0.82526388 | L3: 0.32087572 | M3: -0.10463754 | N3: 0.66604338 | O3: -0.18978676 | P3: -0.082005818 | Q3: -0.14946431 | R3: 0.96416216 | S3: 0.20178846 | T3: 0.42619316 | U3: 0.20692472 | V3: 0.33106279 | W3: -0.32874623 | X3: 0.7195113 | Y3: -0.025365563 | Z3: -0.059429038 | AA3: -0.12646101 | AB3: -0.10537337 | AC3: 0.014599119 | AD3: -0.021407625 | AE3: 0.29825192 | AF3: 0.31363967 | AG3: 0.11771726 | AH3: -0.23471051 | AI3: 0.59728983 | AJ3: 0.028855377 | AK3: -0.15097622 | AL3: 0.25739432 | AM3: 0.016809816
A4: IBRX-100 | B4: {=GEOMEAN(1+K4:AM4)-1} -> 0.14320425 | C4: {=GEOMEAN(1+M4:AM4)-1} -> 0.12454876 | D4: {=GEOMEAN(1+O4:AM4)-1} -> 0.11855353 | E4: {=GEOMEAN(1+Y4:AM4)-1} -> 0.062873665 | F4: {=GEOMEAN(1+AI4:AM4)-1} -> 0.12318035 | G4: 0.255161 | H4: 0.251448 | I4: =(B4-$B$2)/G4 -> 0.018365864 | J4: =(C4-$B$2)/H4 -> -0.055555154 | K4: 0.6614 | L4: 0.2266 | M4: -0.1722 | N4: 0.7461 | O4: -0.0454 | P4: 0.0647 | Q4: -0.0106 | R4: 0.8043 | S4: 0.3357 | T4: 0.4994 | U4: 0.226 | V4: 0.3455 | W4: -0.3123 | X4: 0.5998 | Y4: 0.0134 | Z4: -0.0156 | AA4: -0.0229 | AB4: -0.032 | AC4: 0.0169 | AD4: -0.0253 | AE4: 0.2976 | AF4: 0.3126 | AG4: 0.1267 | AH4: -0.222 | AI4: 0.6217 | AJ4: 0.0279 | AK4: -0.1605 | AL4: 0.2518 | AM4: 0.0204 | AN4: de 28 | AO4: de 26 | AP4: anos negativos
A5: Quintil 1 MF1 | B5: {=GEOMEAN(1+K5:AM5)-1} -> 0.24205877 | C5: {=GEOMEAN(1+M5:AM5)-1} -> 0.23646204 | D5: {=GEOMEAN(1+O5:AM5)-1} -> 0.22827094 | E5: {=GEOMEAN(1+Y5:AM5)-1} -> 0.12817148 | F5: {=GEOMEAN(1+AI5:AM5)-1} -> 0.21426106 | G5: 0.19530499 | H5: 0.1967169 | I5: =(B5-$B$2)/G5 -> 0.53014916 | J5: =(C5-$B$2)/H5 -> 0.49789342 | K5: 0.70734474 | L5: 0.020750755 | M5: -0.12106743 | N5: 1.0538622 | O5: 0.27352873 | P5: 0.26233515 | Q5: 0.53366352 | R5: 0.828813 | S5: 0.64943608 | T5: 0.17995962 | U5: 0.46615282 | V5: 0.18785847 | W5: -0.18676563 | X5: 1.2505186 | Y5: 0.25981317 | Z5: 0.18740135 | AA5: 0.13076471 | AB5: -0.12256286 | AC5: -0.1647112 | AD5: -0.11378303 | AE5: 0.52263111 | AF5: 0.39216225 | AG5: 0.070077583 | AH5: -0.072106929 | AI5: 1.0003592 | AJ5: 0.048103335 | AK5: -0.097773766 | AL5: 0.37072531 | AM5: 0.01808105
AN6: 10 | AO6: 8 | AP6: 7 | AT6: Anos abaixo do IBOV | AU6: % | AV6: Anos negativos | AW6: %
A7: Quintil 1 MF2 | B7: {=GEOMEAN(1+K7:AM7)-1} -> 0.28926423 | C7: {=GEOMEAN(1+M7:AM7)-1} -> 0.25418801 | D7: {=GEOMEAN(1+O7:AM7)-1} -> 0.22766444 | E7: {=GEOMEAN(1+Y7:AM7)-1} -> 0.13254019 | F7: {=GEOMEAN(1+AI7:AM7)-1} -> 0.21688591 | G7: 0.20589768 | H7: 0.20287739 | I7: =(B7-$B$2)/G7 -> 0.7321415 | J7: =(C7-$B$2)/H7 -> 0.57014739 | K7: 0.68528776 | L7: 1.0770674 | M7: -0.00083312214 | N7: 1.6863431 | O7: 0.18214376 | P7: 0.31282132 | Q7: 0.61666686 | R7: 0.67847787 | S7: 0.55460288 | T7: 0.26339559 | U7: 0.56421208 | V7: 0.21122831 | W7: -0.21156972 | X7: 1.1102393 | Y7: 0.3875912 | Z7: 0.23335698 | AA7: 0.11222499 | AB7: -0.10396523 | AC7: -0.2161574 | AD7: -0.046175397 | AE7: 0.44005402 | AF7: 0.16931449 | AG7: 0.16293409 | AH7: -0.029211539 | AI7: 1.2062659 | AJ7: 0.074952355 | AK7: -0.10813911 | AL7: 0.32808486 | AM7: -0.050096904 | AS7: IBOV | AT7: - | AU7: - | AV7: 12 | AW7: =AV7/28 -> 0.42857143
AN8: 8 | AO8: 7 | AP8: 8 | AS8: IBRX-100 | AT8: 11 | AU8: =AT8/28 -> 0.39285714 | AV8: 10 | AW8: =AV8/28 -> 0.35714286
A9: Quintil 1 MF3 | B9: {=GEOMEAN(1+K9:AM9)-1} -> 0.25956337 | C9: {=GEOMEAN(1+M9:AM9)-1} -> 0.25570418 | D9: {=GEOMEAN(1+O9:AM9)-1} -> 0.2472887 | E9: {=GEOMEAN(1+Y9:AM9)-1} -> 0.1412451 | F9: {=GEOMEAN(1+AI9:AM9)-1} -> 0.19924435 | G9: 0.192067 | H9: 0.19299767 | I9: =(B9-$B$2)/G9 -> 0.63022477 | J9: =(C9-$B$2)/H9 -> 0.60718963 | K9: 0.66527527 | L9: 0.034990844 | M9: -0.085710258 | N9: 1.0403263 | O9: 0.41271533 | P9: 0.3488025 | Q9: 0.60743824 | R9: 0.86931065 | S9: 0.35315787 | T9: 0.17828337 | U9: 0.46072055 | V9: 0.41462467 | W9: -0.20132712 | X9: 1.2934879 | Y9: 0.30843976 | Z9: 0.21183435 | AA9: 0.14677181 | AB9: -0.041528308 | AC9: -0.18863806 | AD9: -0.099367666 | AE9: 0.54830967 | AF9: 0.44801785 | AG9: 0.10184653 | AH9: -0.070226456 | AI9: 0.91111331 | AJ9: 0.099333134 | AK9: -0.11273346 | AL9: 0.40540044 | AM9: -0.053177735 | AS9: Quintil 1 MF1 | AT9: 10 | AU9: =AT9/28 -> 0.35714286 | AV9: 7 | AW9: =AV9/28 -> 0.25
AN10: 8 | AO10: 6 | AP10: 8 | AS10: Quintil 1 MF2 | AT10: 8 | AU10: =AT10/28 -> 0.28571429 | AV10: 8 | AW10: =AV10/28 -> 0.28571429
A11: Quintil 1 MF4 | B11: {=GEOMEAN(1+K11:AM11)-1} -> 0.28811983 | C11: {=GEOMEAN(1+M11:AM11)-1} -> 0.25094237 | D11: {=GEOMEAN(1+O11:AM11)-1} -> 0.22053078 | E11: {=GEOMEAN(1+Y11:AM11)-1} -> 0.12585242 | F11: {=GEOMEAN(1+AI11:AM11)-1} -> 0.18698809 | G11: 0.20522958 | H11: 0.20163092 | I11: =(B11-$B$2)/G11 -> 0.7289487 | J11: =(C11-$B$2)/H11 -> 0.55757508 | K11: 0.78328906 | L11: 1.0516477 | M11: 0.017999824 | N11: 1.8440752 | O11: 0.16301632 | P11: 0.24444918 | Q11: 0.46045941 | R11: 0.67847787 | S11: 0.47720074 | T11: 0.23899883 | U11: 0.56421208 | V11: 0.33173504 | W11: -0.19218864 | X11: 1.2542105 | Y11: 0.38476379 | Z11: 0.19548216 | AA11: 0.12975614 | AB11: -0.12899203 | AC11: -0.19992093 | AD11: -0.094191464 | AE11: 0.50684274 | AF11: 0.19781463 | AG11: 0.20810088 | AH11: -0.024259105 | AI11: 0.99210956 | AJ11: 0.11362487 | AK11: -0.13852003 | AL11: 0.30889386 | AM11: -0.05804525 | AS11: Quintil 1 MF3 | AT11: 8 | AU11: =AT11/28 -> 0.28571429 | AV11: 8 | AW11: =AV11/28 -> 0.28571429
AN12: 8 | AO12: 7 | AP12: 7 | AS12: Quintil 1 MF4 | AT12: 8 | AU12: =AT12/28 -> 0.28571429 | AV12: 7 | AW12: =AV12/28 -> 0.25
A13: Quintil 1 MF5 | B13: {=GEOMEAN(1+K13:AM13)-1} -> 0.24178314 | C13: {=GEOMEAN(1+M13:AM13)-1} -> 0.23793536 | D13: {=GEOMEAN(1+O13:AM13)-1} -> 0.22918339 | E13: {=GEOMEAN(1+Y13:AM13)-1} -> 0.12092407 | F13: {=GEOMEAN(1+AI13:AM13)-1} -> 0.19387596 | G13: 0.19623152 | H13: 0.19747862 | I13: =(B13-$B$2)/G13 -> 0.52624136 | J13: =(C13-$B$2)/H13 -> 0.50343357 | K13: 0.58642514 | L13: 0.056968987 | M13: -0.0079992681 | N13: 0.84465881 | O13: 0.32066548 | P13: 0.41391091 | Q13: 0.57379059 | R13: 0.54979805 | S13: 0.60790674 | T13: 0.20756769 | U13: 0.51108608 | V13: 0.38924756 | W13: -0.20159466 | X13: 1.1177399 | Y13: 0.33881492 | Z13: 0.21136584 | AA13: 0.12994899 | AB13: -0.093788547 | AC13: -0.1735725 | AD13: -0.098783874 | AE13: 0.47038308 | AF13: 0.19577116 | AG13: 0.099763266 | AH13: -0.044674982 | AI13: 0.90447195 | AJ13: 0.073946049 | AK13: -0.12403367 | AL13: 0.36772988 | AM13: -0.010191355 | AS13: Quintil 1 MF5 | AT13: 9 | AU13: =AT13/28 -> 0.32142857 | AV13: 8 | AW13: =AV13/28 -> 0.28571429
AN14: 9 | AO14: 7 | AP14: 8 | AS14: Quintil 1 MF6 | AT14: 10 | AU14: =AT14/28 -> 0.35714286 | AV14: 6 | AW14: =AV14/28 -> 0.21428571
A15: Quintil 1 MF6 | B15: {=GEOMEAN(1+K15:AM15)-1} -> 0.21913207 | C15: {=GEOMEAN(1+M15:AM15)-1} -> 0.2132693 | D15: {=GEOMEAN(1+O15:AM15)-1} -> 0.20748259 | E15: {=GEOMEAN(1+Y15:AM15)-1} -> 0.13681872 | F15: {=GEOMEAN(1+AI15:AM15)-1} -> 0.18071661 | G15: 0.18203811 | H15: 0.1814985 | I15: =(B15-$B$2)/G15 -> 0.44284177 | J15: =(C15-$B$2)/H15 -> 0.41185631 | K15: 0.61140899 | L15: 0.050561721 | M15: -0.11720365 | N15: 0.8791531 | O15: 0.19911639 | P15: 0.17876691 | Q15: 0.38553349 | R15: 0.50295363 | S15: 0.55470166 | T15: 0.27148189 | U15: 0.62180764 | V15: 0.075075359 | W15: -0.17346151 | X15: 0.94152592 | Y15: 0.30867483 | Z15: 0.24455136 | AA15: 0.20711725 | AB15: -0.023648516 | AC15: -0.18260515 | AD15: -0.024395363 | AE15: 0.30441663 | AF15: 0.22861081 | AG15: 0.16405119 | AH15: 0.044554717 | AI15: 0.68126158 | AJ15: 0.11056081 | AK15: -0.048720704 | AL15: 0.34003348 | AM15: -0.035889013 | AS15: Quintil 1 MF7 | AT15: 11 | AU15: =AT15/28 -> 0.39285714 | AV15: 7 | AW15: =AV15/28 -> 0.25
AN16: 10 | AO16: 8 | AP16: 6 | AS16: Quintil 1 MF8 | AT16: 11 | AU16: =AT16/28 -> 0.39285714 | AV16: 7 | AW16: =AV16/28 -> 0.25
A17: Quintil 1 MF7 | B17: {=GEOMEAN(1+K17:AM17)-1} -> 0.22036461 | C17: {=GEOMEAN(1+M17:AM17)-1} -> 0.22050743 | D17: {=GEOMEAN(1+O17:AM17)-1} -> 0.22055742 | E17: {=GEOMEAN(1+Y17:AM17)-1} -> 0.13347687 | F17: {=GEOMEAN(1+AI17:AM17)-1} -> 0.1826176 | G17: 0.17737739 | H17: 0.17637358 | I17: =(B17-$B$2)/G17 -> 0.46142644 | J17: =(C17-$B$2)/H17 -> 0.46486234 | K17: 0.41326356 | L17: 0.05047041 | M17: -0.13015612 | N17: 0.71078263 | O17: 0.40563704 | P17: 0.15780838 | Q17: 0.66935573 | R17: 1.0790955 | S17: 0.32408237 | T17: 0.24925596 | U17: 0.56241395 | V17: 0.088348749 | W17: -0.25387221 | X17: 0.8788342 | Y17: 0.25762002 | Z17: 0.21554292 | AA17: 0.2291703 | AB17: -0.055728212 | AC17: -0.067830087 | AD17: -0.043029982 | AE17: 0.22369458 | AF17: 0.25452021 | AG17: 0.17568734 | AH17: -0.00893199 | AI17: 0.59478149 | AJ17: 0.091169069 | AK17: -0.040121368 | AL17: 0.37425709 | AM17: 0.0077298979 | AS17: Quintil 1 MF9 | AT17: 6 | AU17: =AT17/28 -> 0.21428571 | AV17: 4 | AW17: =AV17/28 -> 0.14285714
AN18: 11 | AO18: 9 | AP18: 7 | AS18: Quintil 1 MF10 | AT18: 6 | AU18: =AT18/28 -> 0.21428571 | AV18: 5 | AW18: =AV18/28 -> 0.17857143
A19: Quintil 1 MF8 | B19: {=GEOMEAN(1+K19:AM19)-1} -> 0.21166705 | C19: {=GEOMEAN(1+M19:AM19)-1} -> 0.20630787 | D19: {=GEOMEAN(1+O19:AM19)-1} -> 0.19715138 | E19: {=GEOMEAN(1+Y19:AM19)-1} -> 0.12243325 | F19: {=GEOMEAN(1+AI19:AM19)-1} -> 0.16187259 | G19: 0.17826547 | H19: 0.17714542 | I19: =(B19-$B$2)/G19 -> 0.41033778 | J19: =(C19-$B$2)/H19 -> 0.38267921 | K19: 0.55628717 | L19: 0.063299566 | M19: -0.088230333 | N19: 0.93089403 | O19: 0.21130164 | P19: 0.17876691 | Q19: 0.38553349 | R19: 0.50295363 | S19: 0.50843653 | T19: 0.30287037 | U19: 0.67617321 | V19: 0.040898241 | W19: -0.16343816 | X19: 0.86389968 | Y19: 0.33968257 | Z19: 0.17558035 | AA19: 0.19428595 | AB19: -0.024315159 | AC19: -0.22572892 | AD19: -0.043083923 | AE19: 0.26913368 | AF19: 0.24317885 | AG19: 0.17680868 | AH19: 0.057863176 | AI19: 0.58760762 | AJ19: 0.10785463 | AK19: -0.065294467 | AL19: 0.34062836 | AM19: -0.039309781 | AS19: Quintil 1 MF11 | AT19: 7 | AU19: =AT19/28 -> 0.25 | AV19: 4 | AW19: =AV19/28 -> 0.14285714
AN20: 11 | AO20: 9 | AP20: 7
A21: Quintil 1 MF9 | B21: {=GEOMEAN(1+K21:AM21)-1} -> 0.28377988 | C21: {=GEOMEAN(1+M21:AM21)-1} -> 0.24443413 | D21: {=GEOMEAN(1+O21:AM21)-1} -> 0.23777144 | E21: {=GEOMEAN(1+Y21:AM21)-1} -> 0.17610988 | F21: {=GEOMEAN(1+AI21:AM21)-1} -> 0.19753582 | G21: 0.2033867 | H21: 0.20068003 | I21: =(B21-$B$2)/G21 -> 0.71421522 | J21: =(C21-$B$2)/H21 -> 0.52778611 | K21: 0.77253521 | L21: 1.1547149 | M21: 0.03376244 | N21: 0.71320544 | O21: 0.10974795 | P21: 0.15825828 | Q21: 0.5280851 | R21: 0.96867816 | S21: 0.57707701 | T21: 0.2298359 | U21: 0.3800288 | V21: 0.29059687 | W21: -0.27577061 | X21: 0.87795837 | Y21: 0.40084721 | Z21: 0.13891216 | AA21: 0.16367187 | AB21: 0.001075595 | AC21: -0.011372132 | AD21: -0.00045316112 | AE21: 0.57797222 | AF21: 0.193937 | AG21: 0.26585618 | AH21: 0.056322172 | AI21: 0.80179077 | AJ21: 0.083989025 | AK21: -0.12234686 | AL21: 0.43174357 | AM21: 0.0035179982
AN22: 6 | AO22: 5 | AP22: 4
A23: Quintil 1 MF10 | B23: {=GEOMEAN(1+K23:AM23)-1} -> 0.27789616 | C23: {=GEOMEAN(1+M23:AM23)-1} -> 0.27150875 | D23: {=GEOMEAN(1+O23:AM23)-1} -> 0.25470656 | E23: {=GEOMEAN(1+Y23:AM23)-1} -> 0.20513548 | F23: {=GEOMEAN(1+AI23:AM23)-1} -> 0.19358386 | G23: 0.19352409 | H23: 0.19350409 | I23: =(B23-$B$2)/G23 -> 0.72021096 | J23: =(C23-$B$2)/H23 -> 0.68727616 | K23: 0.58523901 | L23: 0.17938114 | M23: 0.1358368 | N23: 0.9849626 | O23: 0.22896092 | P23: 0.19681871 | Q23: 0.47715586 | R23: 1.3947423 | S23: 0.60956943 | T23: -0.0057833993 | U23: 0.29550025 | V23: 0.34094166 | W23: -0.29707478 | X23: 0.74107456 | Y23: 0.41492225 | Z23: 0.22292199 | AA23: 0.27468591 | AB23: 0.0038596719 | AC23: -0.073329988 | AD23: -0.026631462 | AE23: 0.66004041 | AF23: 0.49494859 | AG23: 0.31386259 | AH23: 0.041282525 | AI23: 0.79028204 | AJ23: 0.16410582 | AK23: -0.14716511 | AL23: 0.35432208 | AM23: 0.006384301
AN24: 6 | AO24: 4 | AP24: 5
A25: Quintil 1 MF11 | B25: {=GEOMEAN(1+K25:AM25)-1} -> 0.27706155 | C25: {=GEOMEAN(1+M25:AM25)-1} -> 0.26346746 | D25: {=GEOMEAN(1+O25:AM25)-1} -> 0.24950743 | E25: {=GEOMEAN(1+Y25:AM25)-1} -> 0.18922617 | F25: {=GEOMEAN(1+AI25:AM25)-1} -> 0.19788016 | G25: 0.19909124 | H25: 0.2007096 | I25: =(B25-$B$2)/G25 -> 0.69587969 | J25: =(C25-$B$2)/H25 -> 0.62253853 | K25: 0.74811748 | L25: 0.24549723 | M25: 0.17590521 | N25: 0.79219904 | O25: 0.15168194 | P25: 0.12232754 | Q25: 0.58726737 | R25: 0.96867816 | S25: 0.62769753 | T25: 0.2298359 | U25: 0.3443387 | V25: 0.30105216 | W25: -0.30069444 | X25: 0.96940916 | Y25: 0.4499887 | Z25: 0.18153383 | AA25: 0.18675117 | AB25: -0.004561252 | AC25: 0.00087092534 | AD25: 0.00014418667 | AE25: 0.57628146 | AF25: 0.29141233 | AG25: 0.2700902 | AH25: 0.041696148 | AI25: 0.90172004 | AJ25: 0.082554964 | AK25: -0.12605046 | AL25: 0.40586381 | AM25: -0.024918951
AN26: 7 | AO26: 5 | AP26: 4
A27: TOP 30 MF4 + Markowitz | C27: {=GEOMEAN(1+M27:AM27)-1} -> 0.23386273 | D27: {=GEOMEAN(1+O27:AM27)-1} -> 0.22096465 | E27: {=GEOMEAN(1+Y27:AM27)-1} -> 0.14134079 | F27: {=GEOMEAN(1+AI27:AM27)-1} -> 0.19893015 | H27: 0.18622659 | J27: =(C27-$B$2)/H27 -> 0.51198238 | M27: -0.023503356 | N27: 1.0274809 | O27: 0.1441376 | P27: 0.33336077 | Q27: 0.39668314 | R27: 0.81491829 | S27: 0.51821826 | T27: 0.28380656 | U27: 0.56921407 | V27: 0.16434663 | W27: -0.21938118 | X27: 0.88334131 | Y27: 0.27790126 | Z27: 0.27383379 | AA27: 0.27703386 | AB27: -0.1022822 | AC27: -0.1548329 | AD27: -0.058443973 | AE27: 0.3854271 | AF27: 0.21511568 | AG27: 0.21126217 | AH27: -0.031543464 | AI27: 1.0696808 | AJ27: 0.098271813 | AK27: -0.14629787 | AL27: 0.26482226 | AM27: 0.0093001541
AO28: 7 | AP28: 7
A29: TOP 30 MF2 + Markowitz | C29: {=GEOMEAN(1+M29:AM29)-1} -> 0.22143203 | D29: {=GEOMEAN(1+O29:AM29)-1} -> 0.21378197 | E29: {=GEOMEAN(1+Y29:AM29)-1} -> 0.12749266 | F29: {=GEOMEAN(1+AI29:AM29)-1} -> 0.16718275 | H29: 0.18532155 | J29: =(C29-$B$2)/H29 -> 0.44740631 | M29: -0.10396762 | N29: 0.94818615 | O29: 0.16664999 | P29: 0.35219681 | Q29: 0.37928435 | R29: 0.91200584 | S29: 0.4918192 | T29: 0.28440421 | U29: 0.51341157 | V29: 0.15854906 | W29: -0.17555585 | X29: 0.82069438 | Y29: 0.29660923 | Z29: 0.30145689 | AA29: 0.27978553 | AB29: -0.10836028 | AC29: -0.15334036 | AD29: -0.073091618 | AE29: 0.35426839 | AF29: 0.21897374 | AG29: 0.17233641 | AH29: -0.045119518 | AI29: 0.87213646 | AJ29: 0.063210576 | AK29: -0.13479098 | AL29: 0.24206083 | AM29: 0.0126832
AO30: 9 | AP30: 7
A31: TOP 30 MF10 + Markowitz | C31: {=GEOMEAN(1+M31:AM31)-1} -> 0.25232398 | D31: {=GEOMEAN(1+O31:AM31)-1} -> 0.24858246 | E31: {=GEOMEAN(1+Y31:AM31)-1} -> 0.17143139 | F31: {=GEOMEAN(1+AI31:AM31)-1} -> 0.18682621 | H31: 0.18373091 | J31: =(C31-$B$2)/H31 -> 0.61941666 | M31: -0.1216271 | N31: 0.92415975 | O31: 0.28370454 | P31: 0.32103401 | Q31: 0.42535886 | R31: 0.96977961 | S31: 0.58263281 | T31: 0.16645816 | U31: 0.45847705 | V31: 0.40231653 | W31: -0.31000107 | X31: 0.93247349 | Y31: 0.38355938 | Z31: 0.22632938 | AA31: 0.25392178 | AB31: -0.1105809 | AC31: -0.042984892 | AD31: -0.00069355464 | AE31: 0.3004608 | AF31: 0.57764747 | AG31: 0.32248897 | AH31: -0.071635289 | AI31: 0.64990386 | AJ31: 0.15372915 | AK31: -0.1236362 | AL31: 0.32008253 | AM31: 0.069270577
AO32: 4 | AP32: 6

Sheet Planilha1
B2: Ranking Sharpe (96-24) | C2: TOP 5 | D2: TOP 10 | E2: TOP 15 | F2: TOP 20 | G2: TOP 30 | I2: Quintil 1 | J2: Quintil 2 | K2: Quintil 3 | L2: Quintil 4 | M2: Quintil 5
B3: MF 1 | C3: 5 | D3: 2 | E3: 4 | F3: 3 | G3: 1 | I3: 1 | J3: 2 | K3: 3 | L3: 4 | M3: 5
B4: MF 2 | C4: 1 | D4: 4 | E4: 3 | F4: 5 | G4: 2 | I4: 1 | J4: 2 | K4: 3 | L4: 4 | M4: 5
B5: MF 3 | C5: 5 | D5: 4 | E5: 3 | F5: 1 | G5: 2 | I5: 1 | J5: 2 | K5: 3 | L5: 4 | M5: 5
B6: MF 4 | C6: 5 | D6: 3 | E6: 4 | F6: 2 | G6: 1 | I6: 1 | J6: 2 | K6: 4 | L6: 3 | M6: 5
B7: MF 5 | C7: 5 | D7: 2 | E7: 3 | F7: 4 | G7: 1 | I7: 2 | J7: 1 | K7: 3 | L7: 4 | M7: 5
B8: MF 6 | C8: 5 | D8: 4 | E8: 3 | F8: 1 | G8: 2 | I8: 1 | J8: 2 | K8: 3 | L8: 4 | M8: 5
B9: MF 7 | C9: 4 | D9: 5 | E9: 3 | F9: 2 | G9: 1 | I9: 1 | J9: 2 | K9: 3 | L9: 4 | M9: 5
B10: MF 8 | C10: 5 | D10: 4 | E10: 3 | F10: 2 | G10: 1 | I10: 2 | J10: 1 | K10: 3 | L10: 4 | M10: 5
B11: MF 9 | C11: 5 | D11: 2 | E11: 4 | F11: 1 | G11: 3 | I11: 1 | J11: 2 | K11: 3 | L11: 4 | M11: 5
B12: MF 10 | C12: 5 | D12: 1 | E12: 4 | F12: 3 | G12: 2 | I12: 1 | J12: 2 | K12: 3 | L12: 4 | M12: 5
B13: MF 11 | C13: 5 | D13: 4 | E13: 3 | F13: 2 | G13: 1 | I13: 1 | J13: 2 | K13: 3 | L13: 4 | M13: 5
B14: pontuação final | C14: =SUM(C3:C13) -> 50 | D14: =SUM(D3:D13) -> 35 | E14: =SUM(E3:E13) -> 37 | F14: =SUM(F3:F13) -> 26 | G14: =SUM(G3:G13) -> 17 | I14: =SUM(I3:I13) -> 13 | J14: =SUM(J3:J13) -> 20 | K14: =SUM(K3:K13) -> 34 | L14: =SUM(L3:L13) -> 43 | M14: =SUM(M3:M13) -> 55
B15: Classificação final | C15: 5 | D15: 3 | E15: 4 | F15: 2 | G15: 1 | I15: 1 | J15: 2 | K15: 3 | L15: 4 | M15: 5
B17: Ranking Sharpe (96-24) | C17: Quintil 1 | D17: Quintil 2 | E17: Quintil 3 | F17: Quintil 4 | G17: Quintil 5
B18: MF 1 | C18: 1 | D18: 2 | E18: 3 | F18: 4 | G18: 5
B19: MF 2 | C19: 1 | D19: 2 | E19: 3 | F19: 4 | G19: 5
B20: MF 3 | C20: 1 | D20: 2 | E20: 3 | F20: 4 | G20: 5
B21: MF 4 | C21: 1 | D21: 2 | E21: 4 | F21: 3 | G21: 5
B22: MF 5 | C22: 2 | D22: 1 | E22: 3 | F22: 4 | G22: 5
B23: MF 6 | C23: 1 | D23: 2 | E23: 3 | F23: 4 | G23: 5
B24: MF 7 | C24: 1 | D24: 2 | E24: 3 | F24: 4 | G24: 5
B25: MF 8 | C25: 2 | D25: 1 | E25: 3 | F25: 4 | G25: 5
B26: MF 9 | C26: 1 | D26: 2 | E26: 3 | F26: 4 | G26: 5
B27: MF 10 | C27: 1 | D27: 2 | E27: 3 | F27: 4 | G27: 5
B28: MF 11 | C28: 1 | D28: 2 | E28: 3 | F28: 4 | G28: 5
B29: pontuação final | C29: =SUM(C18:C28) -> 13 | D29: =SUM(D18:D28) -> 20 | E29: =SUM(E18:E28) -> 34 | F29: =SUM(F18:F28) -> 43 | G29: =SUM(G18:G28) -> 55
B30: Classificação final | C30: 1 | D30: 2 | E30: 3 | F30: 4 | G30: 5
B32: Ordenamento Sharpe (96-24) do quintil 1
B33: MF 2 | C33: 0.7321
B34: MF 4 | C34: 0.7289
B35: MF 3 | C35: 0.6302
B36: MF 1 | C36: 0.5301
B37: MF 5 | C37: 0.5262
B39: Ordenamento Sharpe (96-24) do quintil 1
B40: MF 2 | C40: 0.7321
B41: MF 4 | C41: 0.7289
B42: MF 10 | C42: 0.7202
B43: MF 9 | C43: 0.7142
B44: MF 11 | C44: 0.6959
...

Sheet MARKOWITZ
B2: QUADRO ESTATÍSTICO CARTEIRAS OTIMIZADAS (TOP 30)
B3: CARTEIRA | C3: CAGR (98-24) | D3: DESV PAD (98-24) | E3: SHARPE (98-24)
B4: 100% CDI | C4: 0.13129946 | D4: 0.015906
B5: 100% IBOV | C5: 0.092519379 | D5: 0.26798 | E5: -0.17164944
B6: 100% IBRX-100 | C6: 0.12454876 | D6: 0.251448 | E6: -0.055555154
B7: MF 4 | C7: 0.2547351 | D7: 0.19307941 | E7: 0.6019135
B8: MF 2 | C8: 0.24518159 | D8: 0.19539779 | E8: 0.54587923
B9: MF 10 | C9: 0.26690497 | D9: 0.18688536 | E9: 0.68698252
B10: MF 12 | C10: 0.23386273 | D10: 0.18622659 | E10: 0.51198238
B11: MF 13 | C11: 0.22143203 | D11: 0.1853 | E11: 0.42908497
B12: MF 14 | C12: 0.25232398 | D12: 0.18373091 | E12: 0.61941666

Sheet MF1
B2: QUADRO ESTATÍSTICO MF 1
B3: CARTEIRA | C3: CAGR (96-24) | D3: DESV PAD (96 - 24) | E3: SHARPE (96 - 24)
B4: 100% CDI | C4: 0.138518 | D4: 0.017691
B5: 100% IBOV | C5: 0.11932898 | D5: 0.2722 | E5: -0.070496032
B6: 100% IBRX-100 | C6: 0.14320425 | D6: 0.255161 | E6: 0.018365864
B7: TOP 5 | C7: 0.22564542 | D7: 0.2793523 | E7: 0.31189083
B8: TOP 10 | C8: 0.23882648 | D8: 0.24084492 | E8: 0.41648578
B9: TOP 15 | C9: 0.22157047 | D9: 0.21254925 | E9: 0.3907446
B10: TOP 20 | C10: 0.22031991 | D10: 0.2017502 | E10: 0.40546138
B11: TOP 30 | C11: 0.22814189 | D11: 0.18816383 | E11: 0.47630774
B12: QUINTIL 1 | C12: 0.24205877 | D12: 0.19530499 | E12: 0.53014916
B13: QUINTIL 2 | C13: 0.23101456 | D13: 0.20302245 | E13: 0.45559774
B14: QUINTIL 3 | C14: 0.22707175 | D14: 0.2495047 | E14: 0.35491816
B15: QUINTIL 4 | C15: 0.11420525 | D15: 0.22942859 | E15: -0.10597085
B16: QUINTIL 5 | C16: 0.094627067 | D16: 0.23197177 | E16: -0.18920806

Sheet MF2
B2: QUADRO ESTATÍSTICO MF 2 | F2: QUADRO ESTATÍSTICO MF 3
B3: CARTEIRA | C3: CAGR (96-24) | D3: DESV PAD (96 - 24) | E3: SHARPE (96 - 24) | F3: CARTEIRA | G3: CAGR (96-24) | H3: DESV PAD (96 - 24) | I3: SHARPE (96 - 24)
B4: 100% CDI | C4: 0.138518 | D4: 0.017691 | F4: 100% CDI | G4: 0.138518 | H4: 0.017691
B5: 100% IBOV | C5: 0.11932898 | D5: 0.2722 | E5: -0.070496032 | F5: 100% IBOV | G5: 0.11932898 | H5: 0.2722 | I5: -0.070496032
B6: 100% IBRX-100 | C6: 0.14320425 | D6: 0.255161 | E6: 0.018365864 | F6: 100% IBRX-100 | G6: 0.14320425 | H6: 0.255161 | I6: 0.018365864
B7: TOP 5 | C7: 0.3499685 | D7: 0.30424247 | E7: 0.69500651 | F7: TOP 5 | G7: 0.20630711 | H7: 0.26478233 | I7: 0.25601826
B8: TOP 10 | C8: 0.29112053 | D8: 0.23372215 | E8: 0.65292286 | F8: TOP 10 | G8: 0.26063541 | H8: 0.22265549 | I8: 0.54845904
B9: TOP 15 | C9: 0.27554614 | D9: 0.20949362 | E9: 0.6540922 | F9: TOP 15 | G9: 0.25672052 | H9: 0.20379572 | I9: 0.58000496
B10: TOP 20 | C10: 0.26759114 | D10: 0.20093585 | E10: 0.64235997 | F10: TOP 20 | G10: 0.25744892 | H10: 0.19257057 | I10: 0.61759659
B11: TOP 30 | C11: 0.26792888 | D11: 0.19516788 | E11: 0.6630747 | F11: TOP 30 | G11: 0.24496086 | H11: 0.18203534 | I11: 0.58473735
B12: QUINTIL 1 | C12: 0.28926423 | D12: 0.20589768 | E12: 0.7321415 | F12: QUINTIL 1 | G12: 0.25956337 | H12: 0.192067 | I12: 0.63022477
B13: QUINTIL 2 | C13: 0.22939446 | D13: 0.20319555 | E13: 0.44723648 | F13: QUINTIL 2 | G13: 0.24614553 | H13: 0.19900067 | I13: 0.54084006
B14: QUINTIL 3 | C14: 0.21722205 | D14: 0.20104816 | E14: 0.39146864 | F14: QUINTIL 3 | G14: 0.18450738 | H14: 0.21665367 | I14: 0.21227145
B15: QUINTIL 4 | C15: 0.16585928 | D15: 0.2714864 | E15: 0.1007096 | F15: QUINTIL 4 | G15: 0.15387404 | H15: 0.29636813 | I15: 0.051814095
B16: QUINTIL 5 | C16: 0.098527016 | D16: 0.22170584 | E16: -0.18037856 | F16: QUINTIL 5 | G16: 0.091294809 | H16: 0.22926122 | I16: -0.20597983
B17: QUADRO ESTATÍSTICO MF 4 | F17: QUADRO ESTATÍSTICO MF 5
B18: CARTEIRA | C18: CAGR (96-24) | D18: DESV PAD (96 - 24) | E18: SHARPE (96 - 24) | F18: CARTEIRA | G18: CAGR (96-24) | H18: DESV PAD (96 - 24) | I18: SHARPE (96 - 24)
B19: 100% CDI | C19: 0.138518 | D19: 0.017691 | F19: 100% CDI | G19: 0.138518 | H19: 0.017691
B20: 100% IBOV | C20: 0.11932898 | D20: 0.2722 | E20: -0.070496032 | F20: 100% IBOV | G20: 0.11932898 | H20: 0.2722 | I20: -0.070496032
B21: 100% IBRX-100 | C21: 0.14320425 | D21: 0.255161 | E21: 0.018365864 | F21: 100% IBRX-100 | G21: 0.14320425 | H21: 0.255161 | I21: 0.018365864
B22: TOP 5 | C22: 0.33202353 | D22: 0.29236515 | E22: 0.66186251 | F22: TOP 5 | G22: 0.25768694 | H22: 0.26443017 | I22: 0.4506632
B23: TOP 10 | C23: 0.30181729 | D23: 0.23616326 | E23: 0.69146781 | F23: TOP 10 | G23: 0.25525706 | H23: 0.21918297 | I23: 0.5326101
B24: TOP 15 | C24: 0.28208776 | D24: 0.21485279 | E24: 0.66822388 | F24: TOP 15 | G24: 0.24466166 | H24: 0.2036204 | I24: 0.52128205
B25: TOP 20 | C25: 0.28194022 | D25: 0.2011363 | E25: 0.7130599 | F25: TOP 20 | G25: 0.23899259 | H25: 0.19352142 | I25: 0.51919106
B26: TOP 30 | C26: 0.27827949 | D26: 0.19317299 | E26: 0.72350434 | F26: TOP 30 | G26: 0.24579956 | H26: 0.1849114 | I26: 0.58017822
B27: QUINTIL 1 | C27: 0.28811983 | D27: 0.20522958 | E27: 0.7289487 | F27: QUINTIL 1 | G27: 0.24178314 | H27: 0.19623152 | I27: 0.52624136
B28: QUINTIL 2 | C28: 0.22850302 | D28: 0.20444069 | E28: 0.44015222 | F28: QUINTIL 2 | G28: 0.26717812 | H28: 0.20394286 | I28: 0.63086358
B29: QUINTIL 3 | C29: 0.18452248 | D29: 0.20099402 | E29: 0.22888486 | F29: QUINTIL 3 | G29: 0.17956232 | H29: 0.20732015 | I29: 0.19797558
B30: QUINTIL 4 | C30: 0.2040313 | D30: 0.2667325 | E30: 0.24561425 | F30: QUINTIL 4 | G30: 0.18053958 | H30: 0.2795892 | I30: 0.15029759
B31: QUINTIL 5 | C31: 0.087977862 | D31: 0.22651951 | E31: -0.22311602 | F31: QUINTIL 5 | G31: 0.0801623 | H31: 0.23244793 | I31: -0.25104847

Sheet MF3
B2: QUADRO ESTATÍSTICO MF 3
B3: CARTEIRA | C3: CAGR (96-24) | D3: DESV PAD (96 - 24) | E3: SHARPE (96 - 24)
B4: 100% CDI | C4: 0.138518 | D4: 0.017691
B5: 100% IBOV | C5: 0.11932898 | D5: 0.2722 | E5: -0.070496032
B6: 100% IBRX-100 | C6: 0.14320425 | D6: 0.255161 | E6: 0.018365864
B7: TOP 5 | C7: 0.20630711 | D7: 0.26478233 | E7: 0.25601826
B8: TOP 10 | C8: 0.26063541 | D8: 0.22265549 | E8: 0.54845904
B9: TOP 15 | C9: 0.25672052 | D9: 0.20379572 | E9: 0.58000496
B10: TOP 20 | C10: 0.25744892 | D10: 0.19257057 | E10: 0.61759659
B11: TOP 30 | C11: 0.24496086 | D11: 0.18203534 | E11: 0.58473735
B12: QUINTIL 1 | C12: 0.25956337 | D12: 0.192067 | E12: 0.63022477
B13: QUINTIL 2 | C13: 0.24614553 | D13: 0.19900067 | E13: 0.54084006
B14: QUINTIL 3 | C14: 0.18450738 | D14: 0.21665367 | E14: 0.21227145
B15: QUINTIL 4 | C15: 0.15387404 | D15: 0.29636813 | E15: 0.051814095
B16: QUINTIL 5 | C16: 0.091294809 | D16: 0.22926122 | E16: -0.20597983

Sheet MF4
B2: QUADRO ESTATÍSTICO MF 4
B3: CARTEIRA | C3: CAGR (96-24) | D3: DESV PAD (96 - 24) | E3: SHARPE (96 - 24)
B4: 100% CDI | C4: 0.138518 | D4: 0.017691
B5: 100% IBOV | C5: 0.11932898 | D5: 0.2722 | E5: -0.070496032
B6: 100% IBRX-100 | C6: 0.14320425 | D6: 0.255161 | E6: 0.018365864
B7: TOP 5 | C7: 0.33202353 | D7: 0.29236515 | E7: 0.66186251
B8: TOP 10 | C8: 0.30181729 | D8: 0.23616326 | E8: 0.69146781
B9: TOP 15 | C9: 0.28208776 | D9: 0.21485279 | E9: 0.66822388
B10: TOP 20 | C10: 0.28194022 | D10: 0.2011363 | E10: 0.7130599
B11: TOP 30 | C11: 0.27827949 | D11: 0.19317299 | E11: 0.72350434
B12: QUINTIL 1 | C12: 0.28811983 | D12: 0.20522958 | E12: 0.7289487
B13: QUINTIL 2 | C13: 0.22850302 | D13: 0.20444069 | E13: 0.44015222
B14: QUINTIL 3 | C14: 0.18452248 | D14: 0.20099402 | E14: 0.22888486
B15: QUINTIL 4 | C15: 0.2040313 | D15: 0.2667325 | E15: 0.24561425
B16: QUINTIL 5 | C16: 0.087977862 | D16: 0.22651951 | E16: -0.22311602

Sheet MF5
B2: QUADRO ESTATÍSTICO MF 5
B3: CARTEIRA | C3: CAGR (96-24) | D3: DESV PAD (96 - 24) | E3: SHARPE (96 - 24)
B4: 100% CDI | C4: 0.138518 | D4: 0.017691
B5: 100% IBOV | C5: 0.11932898 | D5: 0.2722 | E5: -0.070496032
B6: 100% IBRX-100 | C6: 0.14320425 | D6: 0.255161 | E6: 0.018365864
B7: TOP 5 | C7: 0.25768694 | D7: 0.26443017 | E7: 0.4506632
B8: TOP 10 | C8: 0.25525706 | D8: 0.21918297 | E8: 0.5326101
B9: TOP 15 | C9: 0.24466166 | D9: 0.2036204 | E9: 0.52128205
B10: TOP 20 | C10: 0.23899259 | D10: 0.19352142 | E10: 0.51919106
B11: TOP 30 | C11: 0.24579956 | D11: 0.1849114 | E11: 0.58017822
B12: QUINTIL 1 | C12: 0.24178314 | D12: 0.19623152 | E12: 0.52624136
B13: QUINTIL 2 | C13: 0.26717812 | D13: 0.20394286 | E13: 0.63086358
B14: QUINTIL 3 | C14: 0.17956232 | D14: 0.20732015 | E14: 0.19797558
B15: QUINTIL 4 | C15: 0.18053958 | D15: 0.2795892 | E15: 0.15029759
B16: QUINTIL 5 | C16: 0.0801623 | D16: 0.23244793 | E16: -0.25104847

Sheet MF6
B2: QUADRO ESTATÍSTICO MF 6
B3: CARTEIRA | C3: CAGR (96-24) | D3: DESV PAD (96 - 24) | E3: SHARPE (96 - 24)
B4: 100% CDI | C4: 0.138518 | D4: 0.017691
B5: 100% IBOV | C5: 0.11932898 | D5: 0.2722 | E5: -0.070496032
B6: 100% IBRX-100 | C6: 0.14320425 | D6: 0.255161 | E6: 0.018365864
B7: TOP 5 | C7: 0.22772121 | D7: 0.24014967 | E7: 0.37144843
B8: TOP 10 | C8: 0.21188808 | D8: 0.19119642 | E8: 0.38374194
B9: TOP 15 | C9: 0.21861448 | D9: 0.17867167 | E9: 0.44828867
B10: TOP 20 | C10: 0.22134838 | D10: 0.17369785 | E10: 0.47686473
B11: TOP 30 | C11: 0.2214286 | D11: 0.17586563 | E11: 0.47144293
B12: QUINTIL 1 | C12: 0.21913207 | D12: 0.18203811 | E12: 0.44284177
B13: QUINTIL 2 | C13: 0.22360257 | D13: 0.20155309 | E13: 0.42214473
B14: QUINTIL 3 | C14: 0.21184465 | D14: 0.21615191 | E14: 0.33923666
B15: QUINTIL 4 | C15: 0.16963677 | D15: 0.22223956 | E15: 0.14002354
B16: QUINTIL 5 | C16: 0.10818709 | D16: 0.31060852 | E16: -0.097649956

Sheet MF7
B2: QUADRO ESTATÍSTICO MF 7
B3: CARTEIRA | C3: CAGR (96-24) | D3: DESV PAD (96 - 24) | E3: SHARPE (96 - 24)
B4: 100% CDI | C4: 0.138518 | D4: 0.017691
B5: 100% IBOV | C5: 0.11932898 | D5: 0.2722 | E5: -0.070496032
B6: 100% IBRX-100 | C6: 0.14320425 | D6: 0.255161 | E6: 0.018365864
B7: TOP 5 | C7: 0.22719727 | D7: 0.2793523 | E7: 0.36650797
B8: TOP 10 | C8: 0.20646776 | D8: 0.24084492 | E8: 0.34776892
B9: TOP 15 | C9: 0.21972257 | D9: 0.21254925 | E9: 0.43752879
B10: TOP 20 | C10: 0.23663898 | D10: 0.2017502 | E10: 0.55085528
B11: TOP 30 | C11: 0.23971692 | D11: 0.18816383 | E11: 0.58198828
B12: QUINTIL 1 | C12: 0.22036461 | D12: 0.19530499 | E12: 0.46142644
B13: QUINTIL 2 | C13: 0.2203572 | D13: 0.20302245 | E13: 0.39457503
B14: QUINTIL 3 | C14: 0.21157815 | D14: 0.2495047 | E14: 0.34344612
B15: QUINTIL 4 | C15: 0.20068655 | D15: 0.22942859 | E15: 0.2649489
B16: QUINTIL 5 | C16: 0.079457858 | D16: 0.23197177 | E16: -0.18320614

Sheet MF8
B2: QUADRO ESTATÍSTICO MF 8
B3: CARTEIRA | C3: CAGR (96-24) | D3: DESV PAD (96 - 24) | E3: SHARPE (96 - 24)
B4: 100% CDI | C4: 0.138518 | D4: 0.017691
B5: 100% IBOV | C5: 0.11932898 | D5: 0.2722 | E5: -0.070496032
B6: 100% IBRX-100 | C6: 0.14320425 | D6: 0.255161 | E6: 0.018365864
B7: TOP 5 | C7: 0.20605365 | D7: 0.23606145 | E7: 0.28609356
B8: TOP 10 | C8: 0.2225737 | D8: 0.18443274 | E8: 0.45575261
B9: TOP 15 | C9: 0.22424266 | D9: 0.17671493 | E9: 0.48510142
B10: TOP 20 | C10: 0.22415389 | D10: 0.17279108 | E10: 0.49560367
B11: TOP 30 | C11: 0.22809976 | D11: 0.17097916 | E11: 0.52393383
B12: QUINTIL 1 | C12: 0.21166705 | D12: 0.17826547 | E12: 0.41033778
B13: QUINTIL 2 | C13: 0.23845935 | D13: 0.20708895 | E13: 0.48260109
B14: QUINTIL 3 | C14: 0.2209914 | D14: 0.20719322 | E14: 0.39805071
B15: QUINTIL 4 | C15: 0.15826988 | D15: 0.22432412 | E15: 0.088050644
B16: QUINTIL 5 | C16: 0.10452839 | D16: 0.32037981 | E16: -0.10609161

Sheet MF9
B2: QUADRO ESTATÍSTICO MF 9
B3: CARTEIRA | C3: CAGR (96-24) | D3: DESV PAD (96 - 24) | E3: SHARPE (96 - 24)
B4: 100% CDI | C4: 0.138518 | D4: 0.017691
B5: 100% IBOV | C5: 0.11932898 | D5: 0.2722 | E5: -0.070496032
B6: 100% IBRX-100 | C6: 0.14320425 | D6: 0.255161 | E6: 0.018365864
B7: TOP 5 | C7: 0.31695516 | D7: 0.27647641 | E7: 0.64539744
B8: TOP 10 | C8: 0.31583661 | D8: 0.23099596 | E8: 0.76762648
B9: TOP 15 | C9: 0.28685912 | D9: 0.21213984 | E9: 0.69926105
B10: TOP 20 | C10: 0.30225407 | D10: 0.20638487 | E10: 0.79335308
B11: TOP 30 | C11: 0.28492984 | D11: 0.19557299 | E11: 0.74863021
B12: QUINTIL 1 | C12: 0.28377988 | D12: 0.2033867 | E12: 0.71421522
B13: QUINTIL 2 | C13: 0.25804471 | D13: 0.20416791 | E13: 0.58543337
B14: QUINTIL 3 | C14: 0.19015019 | D14: 0.20659476 | E14: 0.24992018
B15: QUINTIL 4 | C15: 0.17014265 | D15: 0.26452234 | E15: 0.11955381
B16: QUINTIL 5 | C16: 0.085928316 | D16: 0.22685473 | E16: -0.23182096

Sheet MF10
B2: QUADRO ESTATÍSTICO MF 10
B3: CARTEIRA | C3: CAGR (96-24) | D3: DESV PAD (96 - 24) | E3: SHARPE (96 - 24)
B4: 100% CDI | C4: 0.138518 | D4: 0.017691
B5: 100% IBOV | C5: 0.11932898 | D5: 0.2722 | E5: -0.070496032
B6: 100% IBRX-100 | C6: 0.14320425 | D6: 0.255161 | E6: 0.018365864
B7: TOP 5 | C7: 0.30060192 | D7: 0.26189827 | E7: 0.61888123
B8: TOP 10 | C8: 0.29715341 | D8: 0.2200474 | E8: 0.72091475
B9: TOP 15 | C9: 0.26912481 | D9: 0.19974189 | E9: 0.65387797
B10: TOP 20 | C10: 0.27279207 | D10: 0.19096061 | E10: 0.70315063
B11: TOP 30 | C11: 0.27071167 | D11: 0.1857505 | E11: 0.7116733
B12: QUINTIL 1 | C12: 0.27789616 | D12: 0.19352409 | E12: 0.72021096
B13: QUINTIL 2 | C13: 0.21608508 | D13: 0.19762277 | E13: 0.39250075
B14: QUINTIL 3 | C14: 0.18568152 | D14: 0.20510333 | E14: 0.22995009
B15: QUINTIL 4 | C15: 0.14926152 | D15: 0.22635561 | E15: 0.047463046
B16: QUINTIL 5 | C16: 0.10726878 | D16: 0.30060263 | E16: -0.10395524

Sheet MF11
B2: QUADRO ESTATÍSTICO MF 11
B3: CARTEIRA | C3: CAGR (96-24) | D3: DESV PAD (96 - 24) | E3: SHARPE (96 - 24)
B4: 100% CDI | C4: 0.138518 | D4: 0.017691
B5: 100% IBOV | C5: 0.11932898 | D5: 0.2722 | E5: -0.070496032
B6: 100% IBRX-100 | C6: 0.14320425 | D6: 0.255161 | E6: 0.018365864
B7: TOP 5 | C7: 0.30512786 | D7: 0.26947604 | E7: 0.6182734
B8: TOP 10 | C8: 0.27455686 | D8: 0.21652774 | E8: 0.62827455
B9: TOP 15 | C9: 0.27071915 | D9: 0.20871449 | E9: 0.63340667
B10: TOP 20 | C10: 0.26798446 | D10: 0.1991504 | E10: 0.65009393
B11: TOP 30 | C11: 0.27548688 | D11: 0.19207187 | E11: 0.71311266
B12: QUINTIL 1 | C12: 0.27706155 | D12: 0.19909124 | E12: 0.69587969
B13: QUINTIL 2 | C13: 0.22812134 | D13: 0.20173777 | E13: 0.44415751
B14: QUINTIL 3 | C14: 0.19212212 | D14: 0.20938954 | E14: 0.25600193
B15: QUINTIL 4 | C15: 0.1523084 | D15: 0.20976992 | E15: 0.065740599
B16: QUINTIL 5 | C16: 0.11744854 | D16: 0.28712668 | E16: -0.073380334
